 * Serving Flask app "zinharo_api" (lazy loading)
 * Environment: production
   WARNING: This is a development server. Do not use it in a production deployment.
   Use a production WSGI server instead.
 * Debug mode: off
 * Running on http://0.0.0.0:8080/ (Press CTRL+C to quit)
[2020-05-10 16:53:23,833] ERROR in app: Exception on / [GET]
Traceback (most recent call last):
  File "/home/node-admin/.local/lib/python3.6/site-packages/flask/app.py", line 1950, in full_dispatch_request
    rv = self.dispatch_request()
  File "/home/node-admin/.local/lib/python3.6/site-packages/flask/app.py", line 1926, in dispatch_request
    self.raise_routing_exception(req)
  File "/home/node-admin/.local/lib/python3.6/site-packages/flask/app.py", line 1908, in raise_routing_exception
    raise request.routing_exception
  File "/home/node-admin/.local/lib/python3.6/site-packages/flask/ctx.py", line 350, in match_request
    result = self.url_adapter.match(return_rule=True)
  File "/home/node-admin/.local/lib/python3.6/site-packages/werkzeug/routing.py", line 1945, in match
    raise NotFound()
werkzeug.exceptions.NotFound: 404 Not Found: The requested URL was not found on the server. If you entered the URL manually please check your spelling and try again.

During handling of the above exception, another exception occurred:

Traceback (most recent call last):
  File "/home/node-admin/.local/lib/python3.6/site-packages/flask/app.py", line 2447, in wsgi_app
    response = self.full_dispatch_request()
  File "/home/node-admin/.local/lib/python3.6/site-packages/flask/app.py", line 1952, in full_dispatch_request
    rv = self.handle_user_exception(e)
  File "/home/node-admin/.local/lib/python3.6/site-packages/flask_restful/__init__.py", line 272, in error_router
    return original_handler(e)
  File "/home/node-admin/.local/lib/python3.6/site-packages/flask_restful/__init__.py", line 272, in error_router
    return original_handler(e)
  File "/home/node-admin/.local/lib/python3.6/site-packages/flask_restful/__init__.py", line 272, in error_router
    return original_handler(e)
  [Previous line repeated 2 more times]
  File "/home/node-admin/.local/lib/python3.6/site-packages/flask/app.py", line 1816, in handle_user_exception
    return self.handle_http_exception(e)
  File "/home/node-admin/.local/lib/python3.6/site-packages/flask/app.py", line 1744, in handle_http_exception
    return handler(e)
  File "/home/node-admin/zinharo/zinharo-api/zinharo_api/__init__.py", line 33, in error_404
    return render_template("error_404.html"), 404
  File "/home/node-admin/.local/lib/python3.6/site-packages/flask/templating.py", line 138, in render_template
    ctx.app.jinja_env.get_or_select_template(template_name_or_list),
  File "/home/node-admin/.local/lib/python3.6/site-packages/jinja2/environment.py", line 930, in get_or_select_template
    return self.get_template(template_name_or_list, parent, globals)
  File "/home/node-admin/.local/lib/python3.6/site-packages/jinja2/environment.py", line 883, in get_template
    return self._load_template(name, self.make_globals(globals))
  File "/home/node-admin/.local/lib/python3.6/site-packages/jinja2/environment.py", line 857, in _load_template
    template = self.loader.load(self, name, globals)
  File "/home/node-admin/.local/lib/python3.6/site-packages/jinja2/loaders.py", line 117, in load
    source, filename, uptodate = self.get_source(environment, name)
  File "/home/node-admin/.local/lib/python3.6/site-packages/flask/templating.py", line 60, in get_source
    return self._get_source_fast(environment, template)
  File "/home/node-admin/.local/lib/python3.6/site-packages/flask/templating.py", line 89, in _get_source_fast
    raise TemplateNotFound(template)
jinja2.exceptions.TemplateNotFound: error_404.html
127.0.0.1 - - [10/May/2020 16:53:23] "[35m[1mGET / HTTP/1.1[0m" 500 -
[2020-05-10 17:02:36,190] ERROR in app: Exception on / [GET]
Traceback (most recent call last):
  File "/home/node-admin/.local/lib/python3.6/site-packages/flask/app.py", line 1950, in full_dispatch_request
    rv = self.dispatch_request()
  File "/home/node-admin/.local/lib/python3.6/site-packages/flask/app.py", line 1926, in dispatch_request
    self.raise_routing_exception(req)
  File "/home/node-admin/.local/lib/python3.6/site-packages/flask/app.py", line 1908, in raise_routing_exception
    raise request.routing_exception
  File "/home/node-admin/.local/lib/python3.6/site-packages/flask/ctx.py", line 350, in match_request
    result = self.url_adapter.match(return_rule=True)
  File "/home/node-admin/.local/lib/python3.6/site-packages/werkzeug/routing.py", line 1945, in match
    raise NotFound()
werkzeug.exceptions.NotFound: 404 Not Found: The requested URL was not found on the server. If you entered the URL manually please check your spelling and try again.

During handling of the above exception, another exception occurred:

Traceback (most recent call last):
  File "/home/node-admin/.local/lib/python3.6/site-packages/flask/app.py", line 2447, in wsgi_app
    response = self.full_dispatch_request()
  File "/home/node-admin/.local/lib/python3.6/site-packages/flask/app.py", line 1952, in full_dispatch_request
    rv = self.handle_user_exception(e)
  File "/home/node-admin/.local/lib/python3.6/site-packages/flask_restful/__init__.py", line 272, in error_router
    return original_handler(e)
  File "/home/node-admin/.local/lib/python3.6/site-packages/flask_restful/__init__.py", line 272, in error_router
    return original_handler(e)
  File "/home/node-admin/.local/lib/python3.6/site-packages/flask_restful/__init__.py", line 272, in error_router
    return original_handler(e)
  [Previous line repeated 2 more times]
  File "/home/node-admin/.local/lib/python3.6/site-packages/flask/app.py", line 1816, in handle_user_exception
    return self.handle_http_exception(e)
  File "/home/node-admin/.local/lib/python3.6/site-packages/flask/app.py", line 1744, in handle_http_exception
    return handler(e)
  File "/home/node-admin/zinharo/zinharo-api/zinharo_api/__init__.py", line 33, in error_404
    return render_template("error_404.html"), 404
  File "/home/node-admin/.local/lib/python3.6/site-packages/flask/templating.py", line 138, in render_template
    ctx.app.jinja_env.get_or_select_template(template_name_or_list),
  File "/home/node-admin/.local/lib/python3.6/site-packages/jinja2/environment.py", line 930, in get_or_select_template
    return self.get_template(template_name_or_list, parent, globals)
  File "/home/node-admin/.local/lib/python3.6/site-packages/jinja2/environment.py", line 883, in get_template
    return self._load_template(name, self.make_globals(globals))
  File "/home/node-admin/.local/lib/python3.6/site-packages/jinja2/environment.py", line 857, in _load_template
    template = self.loader.load(self, name, globals)
  File "/home/node-admin/.local/lib/python3.6/site-packages/jinja2/loaders.py", line 117, in load
    source, filename, uptodate = self.get_source(environment, name)
  File "/home/node-admin/.local/lib/python3.6/site-packages/flask/templating.py", line 60, in get_source
    return self._get_source_fast(environment, template)
  File "/home/node-admin/.local/lib/python3.6/site-packages/flask/templating.py", line 89, in _get_source_fast
    raise TemplateNotFound(template)
jinja2.exceptions.TemplateNotFound: error_404.html
127.0.0.1 - - [10/May/2020 17:02:36] "[35m[1mGET / HTTP/1.0[0m" 500 -
[2020-05-10 17:23:22,126] ERROR in app: Exception on / [GET]
Traceback (most recent call last):
  File "/home/node-admin/.local/lib/python3.6/site-packages/flask/app.py", line 1950, in full_dispatch_request
    rv = self.dispatch_request()
  File "/home/node-admin/.local/lib/python3.6/site-packages/flask/app.py", line 1926, in dispatch_request
    self.raise_routing_exception(req)
  File "/home/node-admin/.local/lib/python3.6/site-packages/flask/app.py", line 1908, in raise_routing_exception
    raise request.routing_exception
  File "/home/node-admin/.local/lib/python3.6/site-packages/flask/ctx.py", line 350, in match_request
    result = self.url_adapter.match(return_rule=True)
  File "/home/node-admin/.local/lib/python3.6/site-packages/werkzeug/routing.py", line 1945, in match
    raise NotFound()
werkzeug.exceptions.NotFound: 404 Not Found: The requested URL was not found on the server. If you entered the URL manually please check your spelling and try again.

During handling of the above exception, another exception occurred:

Traceback (most recent call last):
  File "/home/node-admin/.local/lib/python3.6/site-packages/flask/app.py", line 2447, in wsgi_app
    response = self.full_dispatch_request()
  File "/home/node-admin/.local/lib/python3.6/site-packages/flask/app.py", line 1952, in full_dispatch_request
    rv = self.handle_user_exception(e)
  File "/home/node-admin/.local/lib/python3.6/site-packages/flask_restful/__init__.py", line 272, in error_router
    return original_handler(e)
  File "/home/node-admin/.local/lib/python3.6/site-packages/flask_restful/__init__.py", line 272, in error_router
    return original_handler(e)
  File "/home/node-admin/.local/lib/python3.6/site-packages/flask_restful/__init__.py", line 272, in error_router
    return original_handler(e)
  [Previous line repeated 2 more times]
  File "/home/node-admin/.local/lib/python3.6/site-packages/flask/app.py", line 1816, in handle_user_exception
    return self.handle_http_exception(e)
  File "/home/node-admin/.local/lib/python3.6/site-packages/flask/app.py", line 1744, in handle_http_exception
    return handler(e)
  File "/home/node-admin/zinharo/zinharo-api/zinharo_api/__init__.py", line 33, in error_404
    return render_template("error_404.html"), 404
  File "/home/node-admin/.local/lib/python3.6/site-packages/flask/templating.py", line 138, in render_template
    ctx.app.jinja_env.get_or_select_template(template_name_or_list),
  File "/home/node-admin/.local/lib/python3.6/site-packages/jinja2/environment.py", line 930, in get_or_select_template
    return self.get_template(template_name_or_list, parent, globals)
  File "/home/node-admin/.local/lib/python3.6/site-packages/jinja2/environment.py", line 883, in get_template
    return self._load_template(name, self.make_globals(globals))
  File "/home/node-admin/.local/lib/python3.6/site-packages/jinja2/environment.py", line 857, in _load_template
    template = self.loader.load(self, name, globals)
  File "/home/node-admin/.local/lib/python3.6/site-packages/jinja2/loaders.py", line 117, in load
    source, filename, uptodate = self.get_source(environment, name)
  File "/home/node-admin/.local/lib/python3.6/site-packages/flask/templating.py", line 60, in get_source
    return self._get_source_fast(environment, template)
  File "/home/node-admin/.local/lib/python3.6/site-packages/flask/templating.py", line 89, in _get_source_fast
    raise TemplateNotFound(template)
jinja2.exceptions.TemplateNotFound: error_404.html
127.0.0.1 - - [10/May/2020 17:23:22] "[35m[1mGET / HTTP/1.0[0m" 500 -
[2020-05-10 18:12:56,312] ERROR in app: Exception on / [GET]
Traceback (most recent call last):
  File "/home/node-admin/.local/lib/python3.6/site-packages/flask/app.py", line 1950, in full_dispatch_request
    rv = self.dispatch_request()
  File "/home/node-admin/.local/lib/python3.6/site-packages/flask/app.py", line 1926, in dispatch_request
    self.raise_routing_exception(req)
  File "/home/node-admin/.local/lib/python3.6/site-packages/flask/app.py", line 1908, in raise_routing_exception
    raise request.routing_exception
  File "/home/node-admin/.local/lib/python3.6/site-packages/flask/ctx.py", line 350, in match_request
    result = self.url_adapter.match(return_rule=True)
  File "/home/node-admin/.local/lib/python3.6/site-packages/werkzeug/routing.py", line 1945, in match
    raise NotFound()
werkzeug.exceptions.NotFound: 404 Not Found: The requested URL was not found on the server. If you entered the URL manually please check your spelling and try again.

During handling of the above exception, another exception occurred:

Traceback (most recent call last):
  File "/home/node-admin/.local/lib/python3.6/site-packages/flask/app.py", line 2447, in wsgi_app
    response = self.full_dispatch_request()
  File "/home/node-admin/.local/lib/python3.6/site-packages/flask/app.py", line 1952, in full_dispatch_request
    rv = self.handle_user_exception(e)
  File "/home/node-admin/.local/lib/python3.6/site-packages/flask_restful/__init__.py", line 272, in error_router
    return original_handler(e)
  File "/home/node-admin/.local/lib/python3.6/site-packages/flask_restful/__init__.py", line 272, in error_router
    return original_handler(e)
  File "/home/node-admin/.local/lib/python3.6/site-packages/flask_restful/__init__.py", line 272, in error_router
    return original_handler(e)
  [Previous line repeated 2 more times]
  File "/home/node-admin/.local/lib/python3.6/site-packages/flask/app.py", line 1816, in handle_user_exception
    return self.handle_http_exception(e)
  File "/home/node-admin/.local/lib/python3.6/site-packages/flask/app.py", line 1744, in handle_http_exception
    return handler(e)
  File "/home/node-admin/zinharo/zinharo-api/zinharo_api/__init__.py", line 33, in error_404
    return render_template("error_404.html"), 404
  File "/home/node-admin/.local/lib/python3.6/site-packages/flask/templating.py", line 138, in render_template
    ctx.app.jinja_env.get_or_select_template(template_name_or_list),
  File "/home/node-admin/.local/lib/python3.6/site-packages/jinja2/environment.py", line 930, in get_or_select_template
    return self.get_template(template_name_or_list, parent, globals)
  File "/home/node-admin/.local/lib/python3.6/site-packages/jinja2/environment.py", line 883, in get_template
    return self._load_template(name, self.make_globals(globals))
  File "/home/node-admin/.local/lib/python3.6/site-packages/jinja2/environment.py", line 857, in _load_template
    template = self.loader.load(self, name, globals)
  File "/home/node-admin/.local/lib/python3.6/site-packages/jinja2/loaders.py", line 117, in load
    source, filename, uptodate = self.get_source(environment, name)
  File "/home/node-admin/.local/lib/python3.6/site-packages/flask/templating.py", line 60, in get_source
    return self._get_source_fast(environment, template)
  File "/home/node-admin/.local/lib/python3.6/site-packages/flask/templating.py", line 89, in _get_source_fast
    raise TemplateNotFound(template)
jinja2.exceptions.TemplateNotFound: error_404.html
127.0.0.1 - - [10/May/2020 18:12:56] "[35m[1mGET / HTTP/1.0[0m" 500 -
[2020-05-10 19:31:15,623] ERROR in app: Exception on /robots.txt [GET]
Traceback (most recent call last):
  File "/home/node-admin/.local/lib/python3.6/site-packages/flask/app.py", line 1950, in full_dispatch_request
    rv = self.dispatch_request()
  File "/home/node-admin/.local/lib/python3.6/site-packages/flask/app.py", line 1926, in dispatch_request
    self.raise_routing_exception(req)
  File "/home/node-admin/.local/lib/python3.6/site-packages/flask/app.py", line 1908, in raise_routing_exception
    raise request.routing_exception
  File "/home/node-admin/.local/lib/python3.6/site-packages/flask/ctx.py", line 350, in match_request
    result = self.url_adapter.match(return_rule=True)
  File "/home/node-admin/.local/lib/python3.6/site-packages/werkzeug/routing.py", line 1945, in match
    raise NotFound()
werkzeug.exceptions.NotFound: 404 Not Found: The requested URL was not found on the server. If you entered the URL manually please check your spelling and try again.

During handling of the above exception, another exception occurred:

Traceback (most recent call last):
  File "/home/node-admin/.local/lib/python3.6/site-packages/flask/app.py", line 2447, in wsgi_app
    response = self.full_dispatch_request()
  File "/home/node-admin/.local/lib/python3.6/site-packages/flask/app.py", line 1952, in full_dispatch_request
    rv = self.handle_user_exception(e)
  File "/home/node-admin/.local/lib/python3.6/site-packages/flask_restful/__init__.py", line 272, in error_router
    return original_handler(e)
  File "/home/node-admin/.local/lib/python3.6/site-packages/flask_restful/__init__.py", line 272, in error_router
    return original_handler(e)
  File "/home/node-admin/.local/lib/python3.6/site-packages/flask_restful/__init__.py", line 272, in error_router
    return original_handler(e)
  [Previous line repeated 2 more times]
  File "/home/node-admin/.local/lib/python3.6/site-packages/flask/app.py", line 1816, in handle_user_exception
    return self.handle_http_exception(e)
  File "/home/node-admin/.local/lib/python3.6/site-packages/flask/app.py", line 1744, in handle_http_exception
    return handler(e)
  File "/home/node-admin/zinharo/zinharo-api/zinharo_api/__init__.py", line 33, in error_404
    return render_template("error_404.html"), 404
  File "/home/node-admin/.local/lib/python3.6/site-packages/flask/templating.py", line 138, in render_template
    ctx.app.jinja_env.get_or_select_template(template_name_or_list),
  File "/home/node-admin/.local/lib/python3.6/site-packages/jinja2/environment.py", line 930, in get_or_select_template
    return self.get_template(template_name_or_list, parent, globals)
  File "/home/node-admin/.local/lib/python3.6/site-packages/jinja2/environment.py", line 883, in get_template
    return self._load_template(name, self.make_globals(globals))
  File "/home/node-admin/.local/lib/python3.6/site-packages/jinja2/environment.py", line 857, in _load_template
    template = self.loader.load(self, name, globals)
  File "/home/node-admin/.local/lib/python3.6/site-packages/jinja2/loaders.py", line 117, in load
    source, filename, uptodate = self.get_source(environment, name)
  File "/home/node-admin/.local/lib/python3.6/site-packages/flask/templating.py", line 60, in get_source
    return self._get_source_fast(environment, template)
  File "/home/node-admin/.local/lib/python3.6/site-packages/flask/templating.py", line 89, in _get_source_fast
    raise TemplateNotFound(template)
jinja2.exceptions.TemplateNotFound: error_404.html
127.0.0.1 - - [10/May/2020 19:31:15] "[35m[1mGET /robots.txt HTTP/1.0[0m" 500 -
[2020-05-10 19:44:04,071] ERROR in app: Exception on / [GET]
Traceback (most recent call last):
  File "/home/node-admin/.local/lib/python3.6/site-packages/flask/app.py", line 1950, in full_dispatch_request
    rv = self.dispatch_request()
  File "/home/node-admin/.local/lib/python3.6/site-packages/flask/app.py", line 1926, in dispatch_request
    self.raise_routing_exception(req)
  File "/home/node-admin/.local/lib/python3.6/site-packages/flask/app.py", line 1908, in raise_routing_exception
    raise request.routing_exception
  File "/home/node-admin/.local/lib/python3.6/site-packages/flask/ctx.py", line 350, in match_request
    result = self.url_adapter.match(return_rule=True)
  File "/home/node-admin/.local/lib/python3.6/site-packages/werkzeug/routing.py", line 1945, in match
    raise NotFound()
werkzeug.exceptions.NotFound: 404 Not Found: The requested URL was not found on the server. If you entered the URL manually please check your spelling and try again.

During handling of the above exception, another exception occurred:

Traceback (most recent call last):
  File "/home/node-admin/.local/lib/python3.6/site-packages/flask/app.py", line 2447, in wsgi_app
    response = self.full_dispatch_request()
  File "/home/node-admin/.local/lib/python3.6/site-packages/flask/app.py", line 1952, in full_dispatch_request
    rv = self.handle_user_exception(e)
  File "/home/node-admin/.local/lib/python3.6/site-packages/flask_restful/__init__.py", line 272, in error_router
    return original_handler(e)
  File "/home/node-admin/.local/lib/python3.6/site-packages/flask_restful/__init__.py", line 272, in error_router
    return original_handler(e)
  File "/home/node-admin/.local/lib/python3.6/site-packages/flask_restful/__init__.py", line 272, in error_router
    return original_handler(e)
  [Previous line repeated 2 more times]
  File "/home/node-admin/.local/lib/python3.6/site-packages/flask/app.py", line 1816, in handle_user_exception
    return self.handle_http_exception(e)
  File "/home/node-admin/.local/lib/python3.6/site-packages/flask/app.py", line 1744, in handle_http_exception
    return handler(e)
  File "/home/node-admin/zinharo/zinharo-api/zinharo_api/__init__.py", line 33, in error_404
    return render_template("error_404.html"), 404
  File "/home/node-admin/.local/lib/python3.6/site-packages/flask/templating.py", line 138, in render_template
    ctx.app.jinja_env.get_or_select_template(template_name_or_list),
  File "/home/node-admin/.local/lib/python3.6/site-packages/jinja2/environment.py", line 930, in get_or_select_template
    return self.get_template(template_name_or_list, parent, globals)
  File "/home/node-admin/.local/lib/python3.6/site-packages/jinja2/environment.py", line 883, in get_template
    return self._load_template(name, self.make_globals(globals))
  File "/home/node-admin/.local/lib/python3.6/site-packages/jinja2/environment.py", line 857, in _load_template
    template = self.loader.load(self, name, globals)
  File "/home/node-admin/.local/lib/python3.6/site-packages/jinja2/loaders.py", line 117, in load
    source, filename, uptodate = self.get_source(environment, name)
  File "/home/node-admin/.local/lib/python3.6/site-packages/flask/templating.py", line 60, in get_source
    return self._get_source_fast(environment, template)
  File "/home/node-admin/.local/lib/python3.6/site-packages/flask/templating.py", line 89, in _get_source_fast
    raise TemplateNotFound(template)
jinja2.exceptions.TemplateNotFound: error_404.html
127.0.0.1 - - [10/May/2020 19:44:04] "[35m[1mGET / HTTP/1.0[0m" 500 -
[2020-05-10 20:16:20,851] ERROR in app: Exception on /robots.txt [GET]
Traceback (most recent call last):
  File "/home/node-admin/.local/lib/python3.6/site-packages/flask/app.py", line 1950, in full_dispatch_request
    rv = self.dispatch_request()
  File "/home/node-admin/.local/lib/python3.6/site-packages/flask/app.py", line 1926, in dispatch_request
    self.raise_routing_exception(req)
  File "/home/node-admin/.local/lib/python3.6/site-packages/flask/app.py", line 1908, in raise_routing_exception
    raise request.routing_exception
  File "/home/node-admin/.local/lib/python3.6/site-packages/flask/ctx.py", line 350, in match_request
    result = self.url_adapter.match(return_rule=True)
  File "/home/node-admin/.local/lib/python3.6/site-packages/werkzeug/routing.py", line 1945, in match
    raise NotFound()
werkzeug.exceptions.NotFound: 404 Not Found: The requested URL was not found on the server. If you entered the URL manually please check your spelling and try again.

During handling of the above exception, another exception occurred:

Traceback (most recent call last):
  File "/home/node-admin/.local/lib/python3.6/site-packages/flask/app.py", line 2447, in wsgi_app
    response = self.full_dispatch_request()
  File "/home/node-admin/.local/lib/python3.6/site-packages/flask/app.py", line 1952, in full_dispatch_request
    rv = self.handle_user_exception(e)
  File "/home/node-admin/.local/lib/python3.6/site-packages/flask_restful/__init__.py", line 272, in error_router
    return original_handler(e)
  File "/home/node-admin/.local/lib/python3.6/site-packages/flask_restful/__init__.py", line 272, in error_router
    return original_handler(e)
  File "/home/node-admin/.local/lib/python3.6/site-packages/flask_restful/__init__.py", line 272, in error_router
    return original_handler(e)
  [Previous line repeated 2 more times]
  File "/home/node-admin/.local/lib/python3.6/site-packages/flask/app.py", line 1816, in handle_user_exception
    return self.handle_http_exception(e)
  File "/home/node-admin/.local/lib/python3.6/site-packages/flask/app.py", line 1744, in handle_http_exception
    return handler(e)
  File "/home/node-admin/zinharo/zinharo-api/zinharo_api/__init__.py", line 33, in error_404
    return render_template("error_404.html"), 404
  File "/home/node-admin/.local/lib/python3.6/site-packages/flask/templating.py", line 138, in render_template
    ctx.app.jinja_env.get_or_select_template(template_name_or_list),
  File "/home/node-admin/.local/lib/python3.6/site-packages/jinja2/environment.py", line 930, in get_or_select_template
    return self.get_template(template_name_or_list, parent, globals)
  File "/home/node-admin/.local/lib/python3.6/site-packages/jinja2/environment.py", line 883, in get_template
    return self._load_template(name, self.make_globals(globals))
  File "/home/node-admin/.local/lib/python3.6/site-packages/jinja2/environment.py", line 857, in _load_template
    template = self.loader.load(self, name, globals)
  File "/home/node-admin/.local/lib/python3.6/site-packages/jinja2/loaders.py", line 117, in load
    source, filename, uptodate = self.get_source(environment, name)
  File "/home/node-admin/.local/lib/python3.6/site-packages/flask/templating.py", line 60, in get_source
    return self._get_source_fast(environment, template)
  File "/home/node-admin/.local/lib/python3.6/site-packages/flask/templating.py", line 89, in _get_source_fast
    raise TemplateNotFound(template)
jinja2.exceptions.TemplateNotFound: error_404.html
127.0.0.1 - - [10/May/2020 20:16:20] "[35m[1mGET /robots.txt HTTP/1.0[0m" 500 -
[2020-05-10 20:18:36,781] ERROR in app: Exception on / [GET]
Traceback (most recent call last):
  File "/home/node-admin/.local/lib/python3.6/site-packages/flask/app.py", line 1950, in full_dispatch_request
    rv = self.dispatch_request()
  File "/home/node-admin/.local/lib/python3.6/site-packages/flask/app.py", line 1926, in dispatch_request
    self.raise_routing_exception(req)
  File "/home/node-admin/.local/lib/python3.6/site-packages/flask/app.py", line 1908, in raise_routing_exception
    raise request.routing_exception
  File "/home/node-admin/.local/lib/python3.6/site-packages/flask/ctx.py", line 350, in match_request
    result = self.url_adapter.match(return_rule=True)
  File "/home/node-admin/.local/lib/python3.6/site-packages/werkzeug/routing.py", line 1945, in match
    raise NotFound()
werkzeug.exceptions.NotFound: 404 Not Found: The requested URL was not found on the server. If you entered the URL manually please check your spelling and try again.

During handling of the above exception, another exception occurred:

Traceback (most recent call last):
  File "/home/node-admin/.local/lib/python3.6/site-packages/flask/app.py", line 2447, in wsgi_app
    response = self.full_dispatch_request()
  File "/home/node-admin/.local/lib/python3.6/site-packages/flask/app.py", line 1952, in full_dispatch_request
    rv = self.handle_user_exception(e)
  File "/home/node-admin/.local/lib/python3.6/site-packages/flask_restful/__init__.py", line 272, in error_router
    return original_handler(e)
  File "/home/node-admin/.local/lib/python3.6/site-packages/flask_restful/__init__.py", line 272, in error_router
    return original_handler(e)
  File "/home/node-admin/.local/lib/python3.6/site-packages/flask_restful/__init__.py", line 272, in error_router
    return original_handler(e)
  [Previous line repeated 2 more times]
  File "/home/node-admin/.local/lib/python3.6/site-packages/flask/app.py", line 1816, in handle_user_exception
    return self.handle_http_exception(e)
  File "/home/node-admin/.local/lib/python3.6/site-packages/flask/app.py", line 1744, in handle_http_exception
    return handler(e)
  File "/home/node-admin/zinharo/zinharo-api/zinharo_api/__init__.py", line 33, in error_404
    return render_template("error_404.html"), 404
  File "/home/node-admin/.local/lib/python3.6/site-packages/flask/templating.py", line 138, in render_template
    ctx.app.jinja_env.get_or_select_template(template_name_or_list),
  File "/home/node-admin/.local/lib/python3.6/site-packages/jinja2/environment.py", line 930, in get_or_select_template
    return self.get_template(template_name_or_list, parent, globals)
  File "/home/node-admin/.local/lib/python3.6/site-packages/jinja2/environment.py", line 883, in get_template
    return self._load_template(name, self.make_globals(globals))
  File "/home/node-admin/.local/lib/python3.6/site-packages/jinja2/environment.py", line 857, in _load_template
    template = self.loader.load(self, name, globals)
  File "/home/node-admin/.local/lib/python3.6/site-packages/jinja2/loaders.py", line 117, in load
    source, filename, uptodate = self.get_source(environment, name)
  File "/home/node-admin/.local/lib/python3.6/site-packages/flask/templating.py", line 60, in get_source
    return self._get_source_fast(environment, template)
  File "/home/node-admin/.local/lib/python3.6/site-packages/flask/templating.py", line 89, in _get_source_fast
    raise TemplateNotFound(template)
jinja2.exceptions.TemplateNotFound: error_404.html
127.0.0.1 - - [10/May/2020 20:18:36] "[35m[1mGET / HTTP/1.0[0m" 500 -
[2020-05-10 20:35:01,305] ERROR in app: Exception on / [GET]
Traceback (most recent call last):
  File "/home/node-admin/.local/lib/python3.6/site-packages/flask/app.py", line 1950, in full_dispatch_request
    rv = self.dispatch_request()
  File "/home/node-admin/.local/lib/python3.6/site-packages/flask/app.py", line 1926, in dispatch_request
    self.raise_routing_exception(req)
  File "/home/node-admin/.local/lib/python3.6/site-packages/flask/app.py", line 1908, in raise_routing_exception
    raise request.routing_exception
  File "/home/node-admin/.local/lib/python3.6/site-packages/flask/ctx.py", line 350, in match_request
    result = self.url_adapter.match(return_rule=True)
  File "/home/node-admin/.local/lib/python3.6/site-packages/werkzeug/routing.py", line 1945, in match
    raise NotFound()
werkzeug.exceptions.NotFound: 404 Not Found: The requested URL was not found on the server. If you entered the URL manually please check your spelling and try again.

During handling of the above exception, another exception occurred:

Traceback (most recent call last):
  File "/home/node-admin/.local/lib/python3.6/site-packages/flask/app.py", line 2447, in wsgi_app
    response = self.full_dispatch_request()
  File "/home/node-admin/.local/lib/python3.6/site-packages/flask/app.py", line 1952, in full_dispatch_request
    rv = self.handle_user_exception(e)
  File "/home/node-admin/.local/lib/python3.6/site-packages/flask_restful/__init__.py", line 272, in error_router
    return original_handler(e)
  File "/home/node-admin/.local/lib/python3.6/site-packages/flask_restful/__init__.py", line 272, in error_router
    return original_handler(e)
  File "/home/node-admin/.local/lib/python3.6/site-packages/flask_restful/__init__.py", line 272, in error_router
    return original_handler(e)
  [Previous line repeated 2 more times]
  File "/home/node-admin/.local/lib/python3.6/site-packages/flask/app.py", line 1816, in handle_user_exception
    return self.handle_http_exception(e)
  File "/home/node-admin/.local/lib/python3.6/site-packages/flask/app.py", line 1744, in handle_http_exception
    return handler(e)
  File "/home/node-admin/zinharo/zinharo-api/zinharo_api/__init__.py", line 33, in error_404
    return render_template("error_404.html"), 404
  File "/home/node-admin/.local/lib/python3.6/site-packages/flask/templating.py", line 138, in render_template
    ctx.app.jinja_env.get_or_select_template(template_name_or_list),
  File "/home/node-admin/.local/lib/python3.6/site-packages/jinja2/environment.py", line 930, in get_or_select_template
    return self.get_template(template_name_or_list, parent, globals)
  File "/home/node-admin/.local/lib/python3.6/site-packages/jinja2/environment.py", line 883, in get_template
    return self._load_template(name, self.make_globals(globals))
  File "/home/node-admin/.local/lib/python3.6/site-packages/jinja2/environment.py", line 857, in _load_template
    template = self.loader.load(self, name, globals)
  File "/home/node-admin/.local/lib/python3.6/site-packages/jinja2/loaders.py", line 117, in load
    source, filename, uptodate = self.get_source(environment, name)
  File "/home/node-admin/.local/lib/python3.6/site-packages/flask/templating.py", line 60, in get_source
    return self._get_source_fast(environment, template)
  File "/home/node-admin/.local/lib/python3.6/site-packages/flask/templating.py", line 89, in _get_source_fast
    raise TemplateNotFound(template)
jinja2.exceptions.TemplateNotFound: error_404.html
127.0.0.1 - - [10/May/2020 20:35:01] "[35m[1mGET / HTTP/1.0[0m" 500 -
[2020-05-10 20:40:42,550] ERROR in app: Exception on / [GET]
Traceback (most recent call last):
  File "/home/node-admin/.local/lib/python3.6/site-packages/flask/app.py", line 1950, in full_dispatch_request
    rv = self.dispatch_request()
  File "/home/node-admin/.local/lib/python3.6/site-packages/flask/app.py", line 1926, in dispatch_request
    self.raise_routing_exception(req)
  File "/home/node-admin/.local/lib/python3.6/site-packages/flask/app.py", line 1908, in raise_routing_exception
    raise request.routing_exception
  File "/home/node-admin/.local/lib/python3.6/site-packages/flask/ctx.py", line 350, in match_request
    result = self.url_adapter.match(return_rule=True)
  File "/home/node-admin/.local/lib/python3.6/site-packages/werkzeug/routing.py", line 1945, in match
    raise NotFound()
werkzeug.exceptions.NotFound: 404 Not Found: The requested URL was not found on the server. If you entered the URL manually please check your spelling and try again.

During handling of the above exception, another exception occurred:

Traceback (most recent call last):
  File "/home/node-admin/.local/lib/python3.6/site-packages/flask/app.py", line 2447, in wsgi_app
    response = self.full_dispatch_request()
  File "/home/node-admin/.local/lib/python3.6/site-packages/flask/app.py", line 1952, in full_dispatch_request
    rv = self.handle_user_exception(e)
  File "/home/node-admin/.local/lib/python3.6/site-packages/flask_restful/__init__.py", line 272, in error_router
    return original_handler(e)
  File "/home/node-admin/.local/lib/python3.6/site-packages/flask_restful/__init__.py", line 272, in error_router
    return original_handler(e)
  File "/home/node-admin/.local/lib/python3.6/site-packages/flask_restful/__init__.py", line 272, in error_router
    return original_handler(e)
  [Previous line repeated 2 more times]
  File "/home/node-admin/.local/lib/python3.6/site-packages/flask/app.py", line 1816, in handle_user_exception
    return self.handle_http_exception(e)
  File "/home/node-admin/.local/lib/python3.6/site-packages/flask/app.py", line 1744, in handle_http_exception
    return handler(e)
  File "/home/node-admin/zinharo/zinharo-api/zinharo_api/__init__.py", line 33, in error_404
    return render_template("error_404.html"), 404
  File "/home/node-admin/.local/lib/python3.6/site-packages/flask/templating.py", line 138, in render_template
    ctx.app.jinja_env.get_or_select_template(template_name_or_list),
  File "/home/node-admin/.local/lib/python3.6/site-packages/jinja2/environment.py", line 930, in get_or_select_template
    return self.get_template(template_name_or_list, parent, globals)
  File "/home/node-admin/.local/lib/python3.6/site-packages/jinja2/environment.py", line 883, in get_template
    return self._load_template(name, self.make_globals(globals))
  File "/home/node-admin/.local/lib/python3.6/site-packages/jinja2/environment.py", line 857, in _load_template
    template = self.loader.load(self, name, globals)
  File "/home/node-admin/.local/lib/python3.6/site-packages/jinja2/loaders.py", line 117, in load
    source, filename, uptodate = self.get_source(environment, name)
  File "/home/node-admin/.local/lib/python3.6/site-packages/flask/templating.py", line 60, in get_source
    return self._get_source_fast(environment, template)
  File "/home/node-admin/.local/lib/python3.6/site-packages/flask/templating.py", line 89, in _get_source_fast
    raise TemplateNotFound(template)
jinja2.exceptions.TemplateNotFound: error_404.html
127.0.0.1 - - [10/May/2020 20:40:42] "[35m[1mGET / HTTP/1.0[0m" 500 -
[2020-05-10 20:49:40,337] ERROR in app: Exception on / [GET]
Traceback (most recent call last):
  File "/home/node-admin/.local/lib/python3.6/site-packages/flask/app.py", line 1950, in full_dispatch_request
    rv = self.dispatch_request()
  File "/home/node-admin/.local/lib/python3.6/site-packages/flask/app.py", line 1926, in dispatch_request
    self.raise_routing_exception(req)
  File "/home/node-admin/.local/lib/python3.6/site-packages/flask/app.py", line 1908, in raise_routing_exception
    raise request.routing_exception
  File "/home/node-admin/.local/lib/python3.6/site-packages/flask/ctx.py", line 350, in match_request
    result = self.url_adapter.match(return_rule=True)
  File "/home/node-admin/.local/lib/python3.6/site-packages/werkzeug/routing.py", line 1945, in match
    raise NotFound()
werkzeug.exceptions.NotFound: 404 Not Found: The requested URL was not found on the server. If you entered the URL manually please check your spelling and try again.

During handling of the above exception, another exception occurred:

Traceback (most recent call last):
  File "/home/node-admin/.local/lib/python3.6/site-packages/flask/app.py", line 2447, in wsgi_app
    response = self.full_dispatch_request()
  File "/home/node-admin/.local/lib/python3.6/site-packages/flask/app.py", line 1952, in full_dispatch_request
    rv = self.handle_user_exception(e)
  File "/home/node-admin/.local/lib/python3.6/site-packages/flask_restful/__init__.py", line 272, in error_router
    return original_handler(e)
  File "/home/node-admin/.local/lib/python3.6/site-packages/flask_restful/__init__.py", line 272, in error_router
    return original_handler(e)
  File "/home/node-admin/.local/lib/python3.6/site-packages/flask_restful/__init__.py", line 272, in error_router
    return original_handler(e)
  [Previous line repeated 2 more times]
  File "/home/node-admin/.local/lib/python3.6/site-packages/flask/app.py", line 1816, in handle_user_exception
    return self.handle_http_exception(e)
  File "/home/node-admin/.local/lib/python3.6/site-packages/flask/app.py", line 1744, in handle_http_exception
    return handler(e)
  File "/home/node-admin/zinharo/zinharo-api/zinharo_api/__init__.py", line 33, in error_404
    return render_template("error_404.html"), 404
  File "/home/node-admin/.local/lib/python3.6/site-packages/flask/templating.py", line 138, in render_template
    ctx.app.jinja_env.get_or_select_template(template_name_or_list),
  File "/home/node-admin/.local/lib/python3.6/site-packages/jinja2/environment.py", line 930, in get_or_select_template
    return self.get_template(template_name_or_list, parent, globals)
  File "/home/node-admin/.local/lib/python3.6/site-packages/jinja2/environment.py", line 883, in get_template
    return self._load_template(name, self.make_globals(globals))
  File "/home/node-admin/.local/lib/python3.6/site-packages/jinja2/environment.py", line 857, in _load_template
    template = self.loader.load(self, name, globals)
  File "/home/node-admin/.local/lib/python3.6/site-packages/jinja2/loaders.py", line 117, in load
    source, filename, uptodate = self.get_source(environment, name)
  File "/home/node-admin/.local/lib/python3.6/site-packages/flask/templating.py", line 60, in get_source
    return self._get_source_fast(environment, template)
  File "/home/node-admin/.local/lib/python3.6/site-packages/flask/templating.py", line 89, in _get_source_fast
    raise TemplateNotFound(template)
jinja2.exceptions.TemplateNotFound: error_404.html
127.0.0.1 - - [10/May/2020 20:49:40] "[35m[1mGET / HTTP/1.0[0m" 500 -
[2020-05-10 20:49:40,836] ERROR in app: Exception on / [GET]
Traceback (most recent call last):
  File "/home/node-admin/.local/lib/python3.6/site-packages/flask/app.py", line 1950, in full_dispatch_request
    rv = self.dispatch_request()
  File "/home/node-admin/.local/lib/python3.6/site-packages/flask/app.py", line 1926, in dispatch_request
    self.raise_routing_exception(req)
  File "/home/node-admin/.local/lib/python3.6/site-packages/flask/app.py", line 1908, in raise_routing_exception
    raise request.routing_exception
  File "/home/node-admin/.local/lib/python3.6/site-packages/flask/ctx.py", line 350, in match_request
    result = self.url_adapter.match(return_rule=True)
  File "/home/node-admin/.local/lib/python3.6/site-packages/werkzeug/routing.py", line 1945, in match
    raise NotFound()
werkzeug.exceptions.NotFound: 404 Not Found: The requested URL was not found on the server. If you entered the URL manually please check your spelling and try again.

During handling of the above exception, another exception occurred:

Traceback (most recent call last):
  File "/home/node-admin/.local/lib/python3.6/site-packages/flask/app.py", line 2447, in wsgi_app
    response = self.full_dispatch_request()
  File "/home/node-admin/.local/lib/python3.6/site-packages/flask/app.py", line 1952, in full_dispatch_request
    rv = self.handle_user_exception(e)
  File "/home/node-admin/.local/lib/python3.6/site-packages/flask_restful/__init__.py", line 272, in error_router
    return original_handler(e)
  File "/home/node-admin/.local/lib/python3.6/site-packages/flask_restful/__init__.py", line 272, in error_router
    return original_handler(e)
  File "/home/node-admin/.local/lib/python3.6/site-packages/flask_restful/__init__.py", line 272, in error_router
    return original_handler(e)
  [Previous line repeated 2 more times]
  File "/home/node-admin/.local/lib/python3.6/site-packages/flask/app.py", line 1816, in handle_user_exception
    return self.handle_http_exception(e)
  File "/home/node-admin/.local/lib/python3.6/site-packages/flask/app.py", line 1744, in handle_http_exception
    return handler(e)
  File "/home/node-admin/zinharo/zinharo-api/zinharo_api/__init__.py", line 33, in error_404
    return render_template("error_404.html"), 404
  File "/home/node-admin/.local/lib/python3.6/site-packages/flask/templating.py", line 138, in render_template
    ctx.app.jinja_env.get_or_select_template(template_name_or_list),
  File "/home/node-admin/.local/lib/python3.6/site-packages/jinja2/environment.py", line 930, in get_or_select_template
    return self.get_template(template_name_or_list, parent, globals)
  File "/home/node-admin/.local/lib/python3.6/site-packages/jinja2/environment.py", line 883, in get_template
    return self._load_template(name, self.make_globals(globals))
  File "/home/node-admin/.local/lib/python3.6/site-packages/jinja2/environment.py", line 857, in _load_template
    template = self.loader.load(self, name, globals)
  File "/home/node-admin/.local/lib/python3.6/site-packages/jinja2/loaders.py", line 117, in load
    source, filename, uptodate = self.get_source(environment, name)
  File "/home/node-admin/.local/lib/python3.6/site-packages/flask/templating.py", line 60, in get_source
    return self._get_source_fast(environment, template)
  File "/home/node-admin/.local/lib/python3.6/site-packages/flask/templating.py", line 89, in _get_source_fast
    raise TemplateNotFound(template)
jinja2.exceptions.TemplateNotFound: error_404.html
127.0.0.1 - - [10/May/2020 20:49:40] "[35m[1mGET / HTTP/1.0[0m" 500 -
